2024-06-08 21:07:36,117 ERROR: Exception on /funds [POST] [in /Users/ender/Workspace/PythonExperiment/.conda/lib/python3.11/site-packages/flask/app.py:838]
Traceback (most recent call last):
  File "/Users/ender/Workspace/PythonExperiment/.conda/lib/python3.11/site-packages/sqlalchemy/engine/base.py", line 1815, in _execute_context
    context = constructor(
              ^^^^^^^^^^^^
  File "/Users/ender/Workspace/PythonExperiment/.conda/lib/python3.11/site-packages/sqlalchemy/engine/default.py", line 1457, in _init_compiled
    l_param: List[Any] = [
                         ^
  File "/Users/ender/Workspace/PythonExperiment/.conda/lib/python3.11/site-packages/sqlalchemy/engine/default.py", line 1459, in <listcomp>
    flattened_processors[key](compiled_params[key])
  File "lib/sqlalchemy/cyextension/processors.pyx", line 27, in sqlalchemy.cyextension.processors.to_float
ValueError: could not convert string to float: '10%'

The above exception was the direct cause of the following exception:

Traceback (most recent call last):
  File "/Users/ender/Workspace/PythonExperiment/.conda/lib/python3.11/site-packages/flask/app.py", line 1473, in wsgi_app
    response = self.full_dispatch_request()
               ^^^^^^^^^^^^^^^^^^^^^^^^^^^^
  File "/Users/ender/Workspace/PythonExperiment/.conda/lib/python3.11/site-packages/flask/app.py", line 882, in full_dispatch_request
    rv = self.handle_user_exception(e)
         ^^^^^^^^^^^^^^^^^^^^^^^^^^^^^
  File "/Users/ender/Workspace/PythonExperiment/.conda/lib/python3.11/site-packages/flask_cors/extension.py", line 178, in wrapped_function
    return cors_after_request(app.make_response(f(*args, **kwargs)))
                                                ^^^^^^^^^^^^^^^^^^
  File "/Users/ender/Workspace/PythonExperiment/.conda/lib/python3.11/site-packages/flask/app.py", line 880, in full_dispatch_request
    rv = self.dispatch_request()
         ^^^^^^^^^^^^^^^^^^^^^^^
  File "/Users/ender/Workspace/PythonExperiment/.conda/lib/python3.11/site-packages/flask/app.py", line 865, in dispatch_request
    return self.ensure_sync(self.view_functions[rule.endpoint])(**view_args)  # type: ignore[no-any-return]
           ^^^^^^^^^^^^^^^^^^^^^^^^^^^^^^^^^^^^^^^^^^^^^^^^^^^^^^^^^^^^^^^^^
  File "/Users/ender/Workspace/PythonExperiment/.conda/lib/python3.11/site-packages/flask_login/utils.py", line 290, in decorated_view
    return current_app.ensure_sync(func)(*args, **kwargs)
           ^^^^^^^^^^^^^^^^^^^^^^^^^^^^^^^^^^^^^^^^^^^^^^
  File "/Users/ender/Workspace/PythonExperiment/server/app/routes.py", line 70, in create_fund
    db.session.commit()
  File "/Users/ender/Workspace/PythonExperiment/.conda/lib/python3.11/site-packages/sqlalchemy/orm/scoping.py", line 597, in commit
    return self._proxied.commit()
           ^^^^^^^^^^^^^^^^^^^^^^
  File "/Users/ender/Workspace/PythonExperiment/.conda/lib/python3.11/site-packages/sqlalchemy/orm/session.py", line 2017, in commit
    trans.commit(_to_root=True)
  File "<string>", line 2, in commit
  File "/Users/ender/Workspace/PythonExperiment/.conda/lib/python3.11/site-packages/sqlalchemy/orm/state_changes.py", line 139, in _go
    ret_value = fn(self, *arg, **kw)
                ^^^^^^^^^^^^^^^^^^^^
  File "/Users/ender/Workspace/PythonExperiment/.conda/lib/python3.11/site-packages/sqlalchemy/orm/session.py", line 1302, in commit
    self._prepare_impl()
  File "<string>", line 2, in _prepare_impl
  File "/Users/ender/Workspace/PythonExperiment/.conda/lib/python3.11/site-packages/sqlalchemy/orm/state_changes.py", line 139, in _go
    ret_value = fn(self, *arg, **kw)
                ^^^^^^^^^^^^^^^^^^^^
  File "/Users/ender/Workspace/PythonExperiment/.conda/lib/python3.11/site-packages/sqlalchemy/orm/session.py", line 1277, in _prepare_impl
    self.session.flush()
  File "/Users/ender/Workspace/PythonExperiment/.conda/lib/python3.11/site-packages/sqlalchemy/orm/session.py", line 4341, in flush
    self._flush(objects)
  File "/Users/ender/Workspace/PythonExperiment/.conda/lib/python3.11/site-packages/sqlalchemy/orm/session.py", line 4476, in _flush
    with util.safe_reraise():
  File "/Users/ender/Workspace/PythonExperiment/.conda/lib/python3.11/site-packages/sqlalchemy/util/langhelpers.py", line 146, in __exit__
    raise exc_value.with_traceback(exc_tb)
  File "/Users/ender/Workspace/PythonExperiment/.conda/lib/python3.11/site-packages/sqlalchemy/orm/session.py", line 4437, in _flush
    flush_context.execute()
  File "/Users/ender/Workspace/PythonExperiment/.conda/lib/python3.11/site-packages/sqlalchemy/orm/unitofwork.py", line 466, in execute
    rec.execute(self)
  File "/Users/ender/Workspace/PythonExperiment/.conda/lib/python3.11/site-packages/sqlalchemy/orm/unitofwork.py", line 642, in execute
    util.preloaded.orm_persistence.save_obj(
  File "/Users/ender/Workspace/PythonExperiment/.conda/lib/python3.11/site-packages/sqlalchemy/orm/persistence.py", line 93, in save_obj
    _emit_insert_statements(
  File "/Users/ender/Workspace/PythonExperiment/.conda/lib/python3.11/site-packages/sqlalchemy/orm/persistence.py", line 1233, in _emit_insert_statements
    result = connection.execute(
             ^^^^^^^^^^^^^^^^^^^
  File "/Users/ender/Workspace/PythonExperiment/.conda/lib/python3.11/site-packages/sqlalchemy/engine/base.py", line 1418, in execute
    return meth(
           ^^^^^
  File "/Users/ender/Workspace/PythonExperiment/.conda/lib/python3.11/site-packages/sqlalchemy/sql/elements.py", line 515, in _execute_on_connection
    return connection._execute_clauseelement(
           ^^^^^^^^^^^^^^^^^^^^^^^^^^^^^^^^^^
  File "/Users/ender/Workspace/PythonExperiment/.conda/lib/python3.11/site-packages/sqlalchemy/engine/base.py", line 1640, in _execute_clauseelement
    ret = self._execute_context(
          ^^^^^^^^^^^^^^^^^^^^^^
  File "/Users/ender/Workspace/PythonExperiment/.conda/lib/python3.11/site-packages/sqlalchemy/engine/base.py", line 1821, in _execute_context
    self._handle_dbapi_exception(
  File "/Users/ender/Workspace/PythonExperiment/.conda/lib/python3.11/site-packages/sqlalchemy/engine/base.py", line 2353, in _handle_dbapi_exception
    raise sqlalchemy_exception.with_traceback(exc_info[2]) from e
  File "/Users/ender/Workspace/PythonExperiment/.conda/lib/python3.11/site-packages/sqlalchemy/engine/base.py", line 1815, in _execute_context
    context = constructor(
              ^^^^^^^^^^^^
  File "/Users/ender/Workspace/PythonExperiment/.conda/lib/python3.11/site-packages/sqlalchemy/engine/default.py", line 1457, in _init_compiled
    l_param: List[Any] = [
                         ^
  File "/Users/ender/Workspace/PythonExperiment/.conda/lib/python3.11/site-packages/sqlalchemy/engine/default.py", line 1459, in <listcomp>
    flattened_processors[key](compiled_params[key])
  File "lib/sqlalchemy/cyextension/processors.pyx", line 27, in sqlalchemy.cyextension.processors.to_float
sqlalchemy.exc.StatementError: (builtins.ValueError) could not convert string to float: '10%'
[SQL: INSERT INTO fund (name, description, amount, manager, type, pe_ratio, pb_ratio, total_market_value, inception_date, expense_ratio, nav, risk_level, return_rate_1y, return_rate_3y, return_rate_5y) VALUES (?, ?, ?, ?, ?, ?, ?, ?, ?, ?, ?, ?, ?, ?, ?)]
[parameters: [{'name': '三槐基金', 'amount': '1000000', 'risk_level': 'V', 'expense_ratio': '10%', 'description': '用于Web3.0创业投资', 'type': '私募股权基金', 'inception_date': da ... (64 characters truncated) ... , 'total_market_value': None, 'return_rate_1y': None, 'pe_ratio': None, 'pb_ratio': None, 'return_rate_5y': None, 'return_rate_3y': None, 'nav': None}]]
2024-06-08 21:08:33,172 ERROR: Exception on /funds [GET] [in /Users/ender/Workspace/PythonExperiment/.conda/lib/python3.11/site-packages/flask/app.py:838]
Traceback (most recent call last):
  File "/Users/ender/Workspace/PythonExperiment/.conda/lib/python3.11/site-packages/flask/app.py", line 1473, in wsgi_app
    response = self.full_dispatch_request()
               ^^^^^^^^^^^^^^^^^^^^^^^^^^^^
  File "/Users/ender/Workspace/PythonExperiment/.conda/lib/python3.11/site-packages/flask/app.py", line 882, in full_dispatch_request
    rv = self.handle_user_exception(e)
         ^^^^^^^^^^^^^^^^^^^^^^^^^^^^^
  File "/Users/ender/Workspace/PythonExperiment/.conda/lib/python3.11/site-packages/flask_cors/extension.py", line 178, in wrapped_function
    return cors_after_request(app.make_response(f(*args, **kwargs)))
                                                ^^^^^^^^^^^^^^^^^^
  File "/Users/ender/Workspace/PythonExperiment/.conda/lib/python3.11/site-packages/flask/app.py", line 880, in full_dispatch_request
    rv = self.dispatch_request()
         ^^^^^^^^^^^^^^^^^^^^^^^
  File "/Users/ender/Workspace/PythonExperiment/.conda/lib/python3.11/site-packages/flask/app.py", line 865, in dispatch_request
    return self.ensure_sync(self.view_functions[rule.endpoint])(**view_args)  # type: ignore[no-any-return]
           ^^^^^^^^^^^^^^^^^^^^^^^^^^^^^^^^^^^^^^^^^^^^^^^^^^^^^^^^^^^^^^^^^
  File "/Users/ender/Workspace/PythonExperiment/.conda/lib/python3.11/site-packages/flask_login/utils.py", line 290, in decorated_view
    return current_app.ensure_sync(func)(*args, **kwargs)
           ^^^^^^^^^^^^^^^^^^^^^^^^^^^^^^^^^^^^^^^^^^^^^^
  File "/Users/ender/Workspace/PythonExperiment/server/app/routes.py", line 122, in get_all_funds
    funds_list = [
                 ^
  File "/Users/ender/Workspace/PythonExperiment/server/app/routes.py", line 140, in <listcomp>
    'asset_allocation': fund.asset_allocation,
                        ^^^^^^^^^^^^^^^^^^^^^
AttributeError: 'Fund' object has no attribute 'asset_allocation'
2024-06-08 21:10:14,132 INFO: Flask startup [in /Users/ender/Workspace/PythonExperiment/server/app/__init__.py:42]
2024-06-08 21:15:02,243 INFO: Flask startup [in /Users/ender/Workspace/PythonExperiment/server/app/__init__.py:42]
